<robot name="ba_roboter">
  <material name="orange">
    <color rgba="1.0 0.5 0.2 1" />
  </material>

  <link name="map">
    <visual>
      <origin xyz="0.0 0.0 0.0" />
      <geometry>
        <box size="0.5 0.5 0.5" />
      </geometry>
      <material name="blue" />
    </visual>
  </link>

  <link name="odom">
    <visual>
      <origin xyz="0.0 0.0 0.0" />
      <geometry>
        <box size="0.5 0.5 0.5" />
      </geometry>
      <material name="blue" />
    </visual>
  </link>

  <link name="base_link">
    <visual>
      <origin xyz="0.0 0.0 0.0" />
      <geometry>
        <box size="1 1 1" />
      </geometry>
      <material name="red" />
    </visual>
  </link>

  <link name="velodyne">
    <visual>
      <origin xyz="0.0 0.0 0.0" />
      <geometry>
        <box size="0.1 0.1 0.1" />
      </geometry>
      <material name="orange" />
    </visual>
  </link>

  <joint name="odom_joint" type="floating">
    <parent link="map" />
    <child link="odom" />
    <origin xyz="0 0 0" />
  </joint>

  <joint name="base_joint" type="fixed">
    <parent link="odom" />
    <child link="base_link" />
    <origin xyz="0 0 0" />
  </joint>

  <joint name="velodyne_joint" type="fixed">
    <parent link="base_link" />
    <child link="velodyne" />
    <origin xyz="0 0 0" />
  </joint>

</robot>
